Traceback (most recent call last):
  File "/Users/delaram/anaconda3/lib/python3.11/site-packages/jupyter_cache/executors/utils.py", line 58, in single_nb_execution
    executenb(
  File "/Users/delaram/anaconda3/lib/python3.11/site-packages/nbclient/client.py", line 1204, in execute
    return NotebookClient(nb=nb, resources=resources, km=km, **kwargs).execute()
           ^^^^^^^^^^^^^^^^^^^^^^^^^^^^^^^^^^^^^^^^^^^^^^^^^^^^^^^^^^^^^^^^^^^^^
  File "/Users/delaram/anaconda3/lib/python3.11/site-packages/nbclient/util.py", line 84, in wrapped
    return just_run(coro(*args, **kwargs))
           ^^^^^^^^^^^^^^^^^^^^^^^^^^^^^^^
  File "/Users/delaram/anaconda3/lib/python3.11/site-packages/nbclient/util.py", line 62, in just_run
    return loop.run_until_complete(coro)
           ^^^^^^^^^^^^^^^^^^^^^^^^^^^^^
  File "/Users/delaram/anaconda3/lib/python3.11/asyncio/base_events.py", line 653, in run_until_complete
    return future.result()
           ^^^^^^^^^^^^^^^
  File "/Users/delaram/anaconda3/lib/python3.11/site-packages/nbclient/client.py", line 663, in async_execute
    await self.async_execute_cell(
  File "/Users/delaram/anaconda3/lib/python3.11/site-packages/nbclient/client.py", line 965, in async_execute_cell
    await self._check_raise_for_error(cell, cell_index, exec_reply)
  File "/Users/delaram/anaconda3/lib/python3.11/site-packages/nbclient/client.py", line 862, in _check_raise_for_error
    raise CellExecutionError.from_cell_and_msg(cell, exec_reply_content)
nbclient.exceptions.CellExecutionError: An error occurred while executing the following cell:
------------------
%run nuclear_energy_incidents.ipynb
------------------

[0;31m---------------------------------------------------------------------------[0m
[0;31mNameError[0m                                 Traceback (most recent call last)
Cell [0;32mIn[1], line 1[0m
[0;32m----> 1[0m get_ipython()[38;5;241m.[39mrun_line_magic([38;5;124m'[39m[38;5;124mrun[39m[38;5;124m'[39m, [38;5;124m'[39m[38;5;124mnuclear_energy_incidents.ipynb[39m[38;5;124m'[39m)

File [0;32m~/anaconda3/lib/python3.11/site-packages/IPython/core/interactiveshell.py:2432[0m, in [0;36mInteractiveShell.run_line_magic[0;34m(self, magic_name, line, _stack_depth)[0m
[1;32m   2430[0m     kwargs[[38;5;124m'[39m[38;5;124mlocal_ns[39m[38;5;124m'[39m] [38;5;241m=[39m [38;5;28mself[39m[38;5;241m.[39mget_local_scope(stack_depth)
[1;32m   2431[0m [38;5;28;01mwith[39;00m [38;5;28mself[39m[38;5;241m.[39mbuiltin_trap:
[0;32m-> 2432[0m     result [38;5;241m=[39m fn([38;5;241m*[39margs, [38;5;241m*[39m[38;5;241m*[39mkwargs)
[1;32m   2434[0m [38;5;66;03m# The code below prevents the output from being displayed[39;00m
[1;32m   2435[0m [38;5;66;03m# when using magics with decorator @output_can_be_silenced[39;00m
[1;32m   2436[0m [38;5;66;03m# when the last Python token in the expression is a ';'.[39;00m
[1;32m   2437[0m [38;5;28;01mif[39;00m [38;5;28mgetattr[39m(fn, magic[38;5;241m.[39mMAGIC_OUTPUT_CAN_BE_SILENCED, [38;5;28;01mFalse[39;00m):

File [0;32m~/anaconda3/lib/python3.11/site-packages/IPython/core/magics/execution.py:737[0m, in [0;36mExecutionMagics.run[0;34m(self, parameter_s, runner, file_finder)[0m
[1;32m    735[0m     [38;5;28;01mwith[39;00m preserve_keys([38;5;28mself[39m[38;5;241m.[39mshell[38;5;241m.[39muser_ns, [38;5;124m'[39m[38;5;124m__file__[39m[38;5;124m'[39m):
[1;32m    736[0m         [38;5;28mself[39m[38;5;241m.[39mshell[38;5;241m.[39muser_ns[[38;5;124m'[39m[38;5;124m__file__[39m[38;5;124m'[39m] [38;5;241m=[39m filename
[0;32m--> 737[0m         [38;5;28mself[39m[38;5;241m.[39mshell[38;5;241m.[39msafe_execfile_ipy(filename, raise_exceptions[38;5;241m=[39m[38;5;28;01mTrue[39;00m)
[1;32m    738[0m     [38;5;28;01mreturn[39;00m
[1;32m    740[0m [38;5;66;03m# Control the response to exit() calls made by the script being run[39;00m

File [0;32m~/anaconda3/lib/python3.11/site-packages/IPython/core/interactiveshell.py:2954[0m, in [0;36mInteractiveShell.safe_execfile_ipy[0;34m(self, fname, shell_futures, raise_exceptions)[0m
[1;32m   2952[0m result [38;5;241m=[39m [38;5;28mself[39m[38;5;241m.[39mrun_cell(cell, silent[38;5;241m=[39m[38;5;28;01mTrue[39;00m, shell_futures[38;5;241m=[39mshell_futures)
[1;32m   2953[0m [38;5;28;01mif[39;00m raise_exceptions:
[0;32m-> 2954[0m     result[38;5;241m.[39mraise_error()
[1;32m   2955[0m [38;5;28;01melif[39;00m [38;5;129;01mnot[39;00m result[38;5;241m.[39msuccess:
[1;32m   2956[0m     [38;5;28;01mbreak[39;00m

File [0;32m~/anaconda3/lib/python3.11/site-packages/IPython/core/interactiveshell.py:270[0m, in [0;36mExecutionResult.raise_error[0;34m(self)[0m
[1;32m    268[0m     [38;5;28;01mraise[39;00m [38;5;28mself[39m[38;5;241m.[39merror_before_exec
[1;32m    269[0m [38;5;28;01mif[39;00m [38;5;28mself[39m[38;5;241m.[39merror_in_exec [38;5;129;01mis[39;00m [38;5;129;01mnot[39;00m [38;5;28;01mNone[39;00m:
[0;32m--> 270[0m     [38;5;28;01mraise[39;00m [38;5;28mself[39m[38;5;241m.[39merror_in_exec

    [0;31m[... skipping hidden 1 frame][0m

File [0;32m/var/folders/qj/wyb9ssk93x96vj151llh_qwh0000gn/T/ipykernel_66618/2175881116.py:17[0m
[1;32m      1[0m [38;5;66;03m# # import pandas as pd[39;00m
[1;32m      2[0m [38;5;66;03m# # import plotly.express as px[39;00m
[1;32m      3[0m 
[0;32m   (...)[0m
[1;32m     15[0m 
[1;32m     16[0m [38;5;66;03m# # Load the nuclear incidents data[39;00m
[0;32m---> 17[0m incidents_df [38;5;241m=[39m pd[38;5;241m.[39mread_csv([38;5;124m"[39m[38;5;124mnuclear_data/Nuclear Incidents - Sheet3.csv[39m[38;5;124m"[39m)
[1;32m     19[0m [38;5;66;03m# # # Clean and prepare incidents data[39;00m
[1;32m     20[0m [38;5;66;03m# # incidents_df.columns = incidents_df.columns.str.strip()[39;00m
[1;32m     21[0m [38;5;66;03m# # incidents_df.columns.values[6] = "INES level"[39;00m
[0;32m   (...)[0m
[1;32m    115[0m 
[1;32m    116[0m [38;5;66;03m# # Load the sustainable energy data[39;00m
[1;32m    117[0m energy_df [38;5;241m=[39m pd[38;5;241m.[39mread_csv([38;5;124m'[39m[38;5;124mnuclear_data/global-data-on-sustainable-energy (1).csv[39m[38;5;124m'[39m)

[0;31mNameError[0m: name 'pd' is not defined
NameError: name 'pd' is not defined

